Workbook

Sheet All 22 Departments
A1: MEGA MNC EXCEL FORMULA GUIDE | 300+ Formulas | 22 Departments | English & Hinglish
A2: Production|Quality|Utility|Safety|Maintenance|Stores|Purchase|Finance|HR|Sales|Logistics|Planning|IT|Admin|R&D|Academy|Environmental|Costing|Customer Service|Legal|MIS|General
A3: # | B3: Excel Formula / Syntax | C3: Focus / Kaam | D3: English — What It Does | E3: Hinglish — Kaise Use Karein | F3: Hinglish — Formula Ka Naam Kya Hai | G3: MNC Real Example — Kahan Kaam Aata Hai
A4: ► 1. PRODUCTION DEPARTMENT — Utpadan Vibhag
A5: 1 | B5: =SUM(C2:C32) | C5: Monthly Output | D5: Sum of all daily production for the month. | E5: Roz ki production jodke monthly total nikalo. | F5: 'SUM'=Jod — 30 din ka total. | G5: MNC: Monthly production report — total units.
A6: 2 | B6: =D2/E2*100 | C6: Efficiency % | D6: Actual ÷ Planned × 100. | E6: Actual production target se kitni % efficient rahi. | F6: Actual/Target×100 = Efficiency %. | G6: MNC: Shift-wise daily efficiency tracking.
A7: 3 | B7: =IF(D2/E2*100>=95,"World Class",IF(D2/E2*100>=85,"Good",IF(D2/E2*100>=75,"Average","Poor"))) | C7: Efficiency Grade | D7: Auto-grades production efficiency. | E7: Efficiency % se grade auto-assign karo. | F7: IF Nested = % se grade. | G7: MNC: Daily shift grade auto-assign.
A8: 4 | B8: =(E2-F2)/E2*100 | C8: Downtime % | D8: Machine downtime percentage. | E8: Machine kitna % time band rahi. | F8: (Total-Running)/Total×100 = Downtime %. | G8: MNC: Shift report — machine downtime %.
A9: 5 | B9: =F2/E2*100 | C9: Uptime % | D9: Machine running time percentage. | E9: Machine kitna % time chali. | F9: Running/Total×100 = Uptime %. | G9: MNC: Equipment availability for OEE.
A10: 6 | B10: =(E2-F2-G2)/E2*100 | C10: OEE % | D10: Overall Equipment Effectiveness. | E10: Machine ki overall effectiveness % — 85%+ World Class. | F10: OEE=(Avail-DT-Loss)/Total×100. | G10: MNC: TPM — daily OEE tracking.
A11: 7 | B11: =D2*E2 | C11: Production Value ₹ | D11: Units produced × rate = production value. | E11: Units × rate = production ka rupay mein mool. | F11: Units × Rate = ₹ Value. | G11: MNC: Shift production value for costing.
A12: 8 | B12: =SUMIF(B:B,"Line-1",C:C) | C12: Line-wise Output | D12: Total production from Line-1. | E12: Sirf ek line ki production nikalo. | F12: 'SUMIF'=Line filter karo production jodo. | G12: MNC: Multi-line comparison report.
A13: 9 | B13: =D2-E2 | C13: Prod Variance | D13: Actual minus planned production. | E13: Actual aur plan ke beech ka farq. | F13: Actual-Plan=Variance. | G13: MNC: Daily variance — gap analysis.
A14: 10 | B14: =IF(D2>=E2,"Target Met","Short: "&(E2-D2)&" units") | C14: Target Status | D14: Met or shortfall label. | E14: Target met hua ya kitna short raha. | F14: IF=Target check — met ya shortfall. | G14: MNC: Shift manager production alert.
A15: 11 | B15: =D2*E2/60 | C15: Cycle Time min | D15: Units × time / 60 = cycle time in minutes. | E15: Ek unit banane ka cycle time minutes mein. | F15: Units×Time/60=Cycle Time. | G15: MNC: Line balancing — takt vs cycle.
A16: 12 | B16: =3600/D2 | C16: Takt Time sec | D16: Available time ÷ demand = takt time. | E16: Customer demand se takt time nikalo. | F16: 3600/Units = Takt Time seconds. | G16: MNC: Lean — takt time calculation.
A17: 13 | B17: =D2*E2 | C17: Scrap Cost ₹ | D17: Rejected units × cost per unit. | E17: Rejected units × cost = scrap loss. | F17: Rejection×Rate=Scrap Cost ₹. | G17: MNC: Monthly scrap cost — cost reduction.
A18: 14 | B18: =AVERAGE(C2:C32) | C18: Daily Avg Output | D18: Average daily production in month. | E18: Mahine mein roz ka average output. | F18: 'AVERAGE'=Avg daily production. | G18: MNC: Benchmark setting — daily target.
A19: 15 | B19: =LARGE(C2:C32,1) | C19: Best Day Output | D19: Highest single-day production. | E19: Sabse zyada production wale din ki value. | F19: 'LARGE'=Highest day output. | G19: MNC: Best shift/day benchmark.
A20: 16 | B20: =SMALL(C2:C32,1) | C20: Worst Day Output | D20: Lowest single-day production. | E20: Sabse kam production wala din. | F20: 'SMALL'=Lowest day output. | G20: MNC: Identify worst performing shift.
A21: 17 | B21: =COUNTIF(D2:D32,"Planned Shutdown") | C21: Planned Stops | D21: Count of planned shutdown days. | E21: Planned shutdown kitne din the gino. | F21: 'COUNTIF'=Planned shutdown days count. | G21: MNC: Availability factor — OEE input.
A22: 18 | B22: =COUNTIF(D2:D32,"Breakdown") | C22: Breakdown Stops | D22: Count of breakdown stoppages. | E22: Breakdown ki wajah se kitne din ruke. | F22: 'COUNTIF'=Breakdown days gino. | G22: MNC: Monthly reliability tracking.
A23: 19 | B23: =D2/E2 | C23: Yield Ratio | D23: Output units ÷ input material = yield. | E23: Input material se kitna output mila. | F23: Output/Input=Yield Ratio. | G23: MNC: Material yield tracking — waste reduction.
A24: 20 | B24: =(1-D2/E2)*100 | C24: Waste % | D24: Percentage of input wasted. | E24: Input material ka kitna % waste hua. | F24: (1-Yield)×100=Waste %. | G24: MNC: Material efficiency KPI.
A25: 21 | B25: =SUMPRODUCT((B2:B100="A Shift")*(C2:C100)) | C25: Shift-wise Total | D25: Total production of A Shift using SUMPRODUCT. | E25: A Shift ki total production — SUMPRODUCT se. | F25: SUMPRODUCT=Shift filter karke sum. | G25: MNC: Shift comparison — which shift best.
A26: 22 | B26: =D2/E2*100 | C26: Capacity Util % | D26: Actual production ÷ plant capacity × 100. | E26: Plant capacity ka kitna % use hua. | F26: Actual/Capacity×100=Utilization %. | G26: MNC: Capacity planning — over/under.
A27: 23 | B27: =IF(D2/E2*100>100,"Overloaded",IF(D2/E2*100<70,"Underutilized","Optimal")) | C27: Capacity Status | D27: Capacity status label — Optimal/Over/Under. | E27: Capacity status automatically assign karo. | F27: IF=% se status — optimal range 70-100%. | G27: MNC: Resource planning dashboard.
A28: 24 | B28: =D2*24 | C28: Hours in Days | D28: Converts days to hours for time tracking. | E28: Din ko ghante mein convert karo. | F28: Days×24=Hours. | G28: MNC: Downtime hours from days.
A29: 25 | B29: =D2/24 | C29: Days in Hours | D29: Converts hours to days. | E29: Ghante ko din mein convert karo. | F29: Hours/24=Days. | G29: MNC: Reporting — hours to days.
A30: ► 2. QUALITY DEPARTMENT (QA/QC) — Gunvatta Vibhag
A31: 26 | B31: =COUNTIF(C:C,"Rejected")/COUNTA(C:C)*100 | C31: Rejection Rate % | D31: % of parts rejected. | E31: Rejection % nikalo. | F31: Rejected/Total×100=Rejection %. | G31: MNC: Daily production rejection %.
A32: 27 | B32: =COUNTIF(C:C,"Pass")/COUNTA(C:C)*100 | C32: FPY % | D32: First Pass Yield %. | E32: Pehli baar pass % nikalo — FPY. | F32: Pass/Total×100=FPY %. | G32: MNC: Quality efficiency KPI.
A33: 28 | B33: =(COUNTIF(C:C,"Rejected")/COUNTA(C:C))*1000000 | C33: DPPM | D33: Defective Parts Per Million. | E33: DPPM = international quality KPI. | F33: (Rejected/Total)×10 lakh=DPPM. | G33: MNC: Customer quality report.
A34: 29 | B34: =IF(AND(D2>=E2,D2<=F2),"ACCEPT","REJECT") | C34: Accept/Reject | D34: Auto inspection decision. | E34: Tolerance se auto ACCEPT/REJECT. | F34: IF+AND=Tolerance check. | G34: MNC: Inspection auto-decision.
A35: 30 | B35: =D2*E2*F2 | C35: RPN FMEA | D35: Severity × Occurrence × Detection. | E35: FMEA ke liye RPN nikalo. | F35: S×O×D=RPN — risk priority. | G35: MNC: FMEA risk score.
A36: 31 | B36: =IF(D2>=100,"High",IF(D2>=50,"Medium","Low")) | C36: Risk Level | D36: FMEA risk classification. | E36: RPN se risk level assign karo. | F36: IF Nested=RPN se level. | G36: MNC: FMEA action prioritization.
A37: 32 | B37: =COUNTIFS(B:B,"Vendor-A",C:C,"Rejected") | C37: Vendor Rejection | D37: Vendor-specific rejection count. | E37: Ek vendor ke rejected parts gino. | F37: 'COUNTIFS'=Vendor+Rejected count. | G37: MNC: Vendor quality scorecard.
A38: 33 | B38: =IF(D2>=95,"A",IF(D2>=85,"B",IF(D2>=75,"C","D"))) | C38: Vendor Grade | D38: A/B/C/D vendor quality grade. | E38: Vendor score se grade assign karo. | F38: IF Nested=Score se grade. | G38: MNC: Vendor evaluation system.
A39: 34 | B39: =IF(DATEDIF(B2,TODAY(),"D")>7,"OVERDUE","Open") | C39: NCR Overdue | D39: NCR open beyond 7 days flag. | E39: 7 din se zyada khula NCR flag karo. | F39: IF+DATEDIF=7 day check. | G39: MNC: NCR closure monitoring.
A40: 35 | B40: =STDEV(D2:D100)/AVERAGE(D2:D100)*100 | C40: COV % | D40: Coefficient of Variation — process consistency. | E40: Process variation % nikalo. | F40: StdDev/Avg×100=COV %. | G40: MNC: SPC process consistency.
...

Sheet Department Index
A1: 22 DEPARTMENTS — FORMULA COUNT & KEY KPIs INDEX
A2: Dept # | B2: Department | C2: Key KPI Formulas | D2: Real MNC Application
A3: 1 | B3: PRODUCTION | C3: OEE% | Efficiency% | Downtime% | Scrap Cost | Takt Time | D3: Shift tracking, line comparison, scrap analysis
A4: 2 | B4: QUALITY | C4: DPPM | FPY% | RPN(FMEA) | ACCEPT/REJECT | Cp | D4: Inspection, vendor quality, CAPA, SPC
A5: 3 | B5: UTILITY | C5: SEC | OEE% | MTBF | Water Balance | PM% | D5: Energy audit, BEE reporting, ZLD
A6: 4 | B6: SAFETY | C6: LTIFR | TRIFR | PPE% | RPN | Safe Days | D6: Safety dashboard, HIRA, audit compliance
A7: 5 | B7: MAINTENANCE | C7: MTBF | MTTR | PM% | Availability% | Work Orders | D7: TPM, breakdown tracking, spare management
A8: 6 | B8: STORES | C8: Closing Stock | Reorder Alert | EOQ | Days of Stock | D8: Bin card, inventory valuation, ABC analysis
A9: 7 | B9: PURCHASE | C9: Saving% | Lead Time | L1/L2/L3 Rank | Payment Due | D9: Procurement KPI, vendor management
A10: 8 | B10: FINANCE | C10: GST | EMI | NPV | IRR | Growth% | Margin% | D10: P&L, budget control, investment analysis
A11: 9 | B11: HR | C11: Tenure | Net Salary | PF | ESIC | Attrition% | D11: Payroll, appraisal, headcount analytics
A12: 10 | B12: SALES | C12: Achievement% | Win Rate% | Commission | NPS | D12: Leaderboard, target tracking, territory analysis
A13: 11 | B13: LOGISTICS | C13: OTD% | Transit Days | Fill Rate% | Freight/Unit | D13: Delivery performance, freight cost analysis
... A24: 22 | B24: GENERAL | C24: IF | SUM | VLOOKUP | INDEX+MATCH | TEXT | DATE | STAT | D24: Universal formulas for all departments
